Workbook

Sheet raw
A1: 단위 : 원 (VAT 포함) | D1: =SUBTOTAL(9,D4:D202) -> 127461579592 | E1: =SUBTOTAL(9,E4:E202) -> 3.5405994e+09 | G1: =SUBTOTAL(9,G4:G202) -> 16880 | J1: =SUBTOTAL(9,J4:J202) -> 2.7097282e+10 | K1: =SUBTOTAL(9,K4:K202) -> 2.3159231e+10 | L1: =SUBTOTAL(9,L4:L195) -> 146.10044 | M1: =SUBTOTAL(9,M4:M195) -> 673127350 | N1: =SUBTOTAL(9,N4:N195) -> 0 | O1: =SUBTOTAL(9,O4:O195) -> 532270500 | P1: =SUBTOTAL(9,P4:P195) -> 0 | Q1: =SUBTOTAL(9,Q4:Q195) -> 215127190 | R1: =SUBTOTAL(9,R4:R195) -> 320691250 | S1: =SUBTOTAL(9,S4:S195) -> 1225072458 | ... BB1: =SUBTOTAL(9,BB4:BB195) -> 2671463691 | BC1: =SUBTOTAL(9,BC4:BC202) -> 2667121147 | BD1: =SUBTOTAL(9,BD4:BD202) -> 2382685134
A2: 거래처정보 | D2: 계약정보 | J2: 누적 | M2: 2024.12 | O2: 2025.01 | Q2: 2025.02 | S2: 2025.03 | U2: 2025.04 | W2: 2025.05 | Y2: 2025.06 | AA2: 2025.07 | AC2: 2025.08 | AE2: 2025.09 | AG2: 2025.10 | AI2: 2025.11 | AK2: 2025.12 | AM2: 1월 | AO2: 2월 | AQ2: 3월 | AS2: 4월 | AU2: 5월 | AW2: 6월 | AY2: 7월 | BA2: 8월 | BC2: 9월
A3: no. | B3: 실납처 | C3: 실납처명 | D3: 계약금액 | E3: 월목표 | F3: 유형 | G3: 병상수 | H3: 계약시작 | I3: 회전 | J3: 매출누계 | K3: 수금누계 | L3: 수금율 | M3: 매출 | N3: 수금 | O3: 매출 | P3: 수금 | Q3: 매출 | R3: 수금 | S3: 매출 | T3: 수금 | U3: 매출 | V3: 수금 | W3: 매출 | X3: 수금 | Y3: 매출 | Z3: 수금 | AA3: 매출 | AB3: 수금 | AC3: 매출 | AD3: 수금 | AE3: 매출 | AF3: 수금 | AG3: 매출 | AH3: 수금 | AI3: 매출 | AJ3: 수금 | AK3: 매출 | AL3: 수금 | AM3: 매출 | AN3: 수금 | AO3: 매출 | AP3: 수금 | AQ3: 매출 | AR3: 수금 | AS3: 매출 | AT3: 수금 | AU3: 매출 | AV3: 수금 | AW3: 매출 | AX3: 수금 | AY3: 매출 | AZ3: 수금 | BA3: 매출 | BB3: 수금 | BC3: 매출 | BD3: 수금
A4: 1 | B4: 10031447 | C4: 신촌연세병원 | D4: 654495400 | E4: =D4/36 -> 18180428 | F4: 사용량비례형 | G4: 72 | H4: 2025-08-22 | I4: 30일 | J4: =M4+O4+Q4+S4+U4+W4+Y4+AA4+AC4+AE4+AG4+AI4+AK4+AM4+AO4+AQ4+AS4+AU4+AW4+AY4+BA4+BC4 -> 66332001 | K4: =N4+P4+R4+T4+V4+X4+Z4+AB4+AD4+AF4+AH4+AJ4+AL4+AN4+AP4+AR4+AT4+AV4+AX4+AZ4+BB4+BD4 -> 50328000 | L4: =K4/J4 -> 0.7587288 | M4: 0 | N4: 0 | O4: 0 | P4: 0 | Q4: 0 | R4: 0 | S4: 0 | T4: 0 | U4: 0 | V4: 0 | W4: 0 | X4: 0 | Y4: 0 | Z4: 0 | AA4: 0 | AB4: 0 | AC4: 0 | AD4: 0 | AE4: 0 | AF4: 0 | AG4: 0 | AH4: 0 | AI4: 0 | AJ4: 0 | AK4: 3524000 | AL4: 0 | AM4: 7135000.4 | AN4: 0 | AO4: 6917000.2 | AP4: 10659000 | AQ4: 6985000 | AR4: 6917000 | AS4: 6243000.5 | AT4: 6985000 | AU4: 7102000.4 | AV4: 6243000 | AW4: 5877999.6 | AX4: 7102000 | AY4: 6544000.1 | AZ4: 5878000 | BA4: 8327000 | BB4: 0 | BC4: 7677000 | BD4: 6544000
A5: 2 | B5: 10008739 | C5: 씨엠병원 | D5: 663274000 | E5: =D5/36 -> 18424278 | F5: 사용량비례형 | G5: 105 | H5: 2025-09-22 | I5: 30일 | J5: =M5+O5+Q5+S5+U5+W5+Y5+AA5+AC5+AE5+AG5+AI5+AK5+AM5+AO5+AQ5+AS5+AU5+AW5+AY5+BA5+BC5 -> 68248828 | K5: =N5+P5+R5+T5+V5+X5+Z5+AB5+AD5+AF5+AH5+AJ5+AL5+AN5+AP5+AR5+AT5+AV5+AX5+AZ5+BB5+BD5 -> 19134612 | L5: =K5/J5 -> 0.28036543 | M5: 0 | N5: 0 | O5: 0 | P5: 0 | Q5: 0 | R5: 0 | S5: 0 | T5: 0 | U5: 0 | V5: 0 | W5: 0 | X5: 0 | Y5: 0 | Z5: 0 | AA5: 0 | AB5: 0 | AC5: 0 | AD5: 0 | AE5: 0 | AF5: 0 | AG5: 0 | AH5: 0 | AI5: 0 | AJ5: 0 | AK5: 3742000 | AL5: 0 | AM5: 10791000 | AN5: 0 | AO5: 15583000 | AP5: 0 | AQ5: 8312000.4 | AR5: 0 | AS5: 7053180.2 | AT5: 0 | AU5: 112901.8 | AV5: 0 | AW5: 3513779.5 | AX5: 0 | AY5: 8420148 | AZ5: 11420502 | BA5: 5470818 | BB5: 0 | BC5: 5250000 | BD5: 7714110
A6: 3 | B6: 10046812 | C6: 의료법인은성의료재단좋은선린병원 | D6: 837272000 | E6: =D6/36 -> 23257556 | F6: 사용량비례형 | G6: 120 | H6: 2025-06-27 | I6: 30일 | J6: =M6+O6+Q6+S6+U6+W6+Y6+AA6+AC6+AE6+AG6+AI6+AK6+AM6+AO6+AQ6+AS6+AU6+AW6+AY6+BA6+BC6 -> 2.07291e+08 | K6: =N6+P6+R6+T6+V6+X6+Z6+AB6+AD6+AF6+AH6+AJ6+AL6+AN6+AP6+AR6+AT6+AV6+AX6+AZ6+BB6+BD6 -> 184212000 | L6: =K6/J6 -> 0.88866376 | M6: 0 | N6: 0 | O6: 0 | P6: 0 | Q6: 0 | R6: 0 | S6: 0 | T6: 0 | U6: 0 | V6: 0 | W6: 0 | X6: 0 | Y6: 0 | Z6: 0 | AA6: 0 | AB6: 0 | AC6: 0 | AD6: 0 | AE6: 0 | AF6: 0 | AG6: 0 | AH6: 0 | AI6: 0 | AJ6: 0 | AK6: 13449000 | AL6: 0 | AM6: 29421000 | AN6: 13449000 | AO6: 21711000 | AP6: 29421000 | AQ6: 20898000 | AR6: 21711000 | AS6: 23113000 | AT6: 20898000 | AU6: 17026000 | AV6: 23113000 | AW6: 17061000 | AX6: 17026000 | AY6: 20226000 | AZ6: 17061000 | BA6: 21307000 | BB6: 20226000 | BC6: 23079000 | BD6: 21307000
A7: 4 | B7: 10060702 | C7: 동탄시티병원 | D7: 536550000 | E7: =D7/36 -> 14904167 | F7: 사용량비례형 | G7: 90 | H7: 2025-07-31 | I7: 30일 | J7: =M7+O7+Q7+S7+U7+W7+Y7+AA7+AC7+AE7+AG7+AI7+AK7+AM7+AO7+AQ7+AS7+AU7+AW7+AY7+BA7+BC7 -> 1.09792e+08 | K7: =N7+P7+R7+T7+V7+X7+Z7+AB7+AD7+AF7+AH7+AJ7+AL7+AN7+AP7+AR7+AT7+AV7+AX7+AZ7+BB7+BD7 -> 99488000 | L7: =K7/J7 -> 0.90614981 | M7: 0 | N7: 0 | O7: 0 | P7: 0 | Q7: 0 | R7: 0 | S7: 0 | T7: 0 | U7: 0 | V7: 0 | W7: 0 | X7: 0 | Y7: 0 | Z7: 0 | AA7: 0 | AB7: 0 | AC7: 0 | AD7: 0 | AE7: 0 | AF7: 0 | AG7: 0 | AH7: 0 | AI7: 1840000 | AJ7: 0 | AK7: 7312000 | AL7: 0 | AM7: 13760000 | AN7: 1840000 | AO7: 12512000 | AP7: 7312000 | AQ7: 8703999.7 | AR7: 26272000 | AS7: 8576000.4 | AT7: 8704000 | AU7: 12784000 | AV7: 0 | AW7: 12928000 | AX7: 21360000 | AY7: 12064000 | AZ7: 12928000 | BA7: 9008000 | BB7: 12064000 | BC7: 10304000 | BD7: 9008000
A8: 5 | B8: 10032706 | C8: 의료법인백성의료재단안중백병원 | D8: 429235000 | E8: =D8/36 -> 11923194 | F8: 사용량비례형 | G8: 60 | H8: 2025-07-10 | I8: 30일 | J8: =M8+O8+Q8+S8+U8+W8+Y8+AA8+AC8+AE8+AG8+AI8+AK8+AM8+AO8+AQ8+AS8+AU8+AW8+AY8+BA8+BC8 -> 1.31264e+08 | K8: =N8+P8+R8+T8+V8+X8+Z8+AB8+AD8+AF8+AH8+AJ8+AL8+AN8+AP8+AR8+AT8+AV8+AX8+AZ8+BB8+BD8 -> 72643000 | L8: =K8/J8 -> 0.55341144 | M8: 0 | N8: 0 | O8: 0 | P8: 0 | Q8: 0 | R8: 0 | S8: 0 | T8: 0 | U8: 0 | V8: 0 | W8: 0 | X8: 0 | Y8: 0 | Z8: 0 | AA8: 0 | AB8: 0 | AC8: 0 | AD8: 0 | AE8: 0 | AF8: 0 | AG8: 0 | AH8: 0 | AI8: 0 | AJ8: 0 | AK8: 8413000 | AL8: 0 | AM8: 12362000 | AN8: 0 | AO8: 15868000 | AP8: 8413000 | AQ8: 14405000 | AR8: 0 | AS8: 0 | AT8: 12362000 | AU8: 34152000 | AV8: 0 | AW8: 16497000 | AX8: 15868000 | AY8: 13400000 | AZ8: 15000000 | BA8: 8190000 | BB8: 18000000 | BC8: 7977000 | BD8: 3000000
A9: 6 | B9: 10045809 | C9: 의료법인영동의료재단의정부백병원 | D9: 605334000 | E9: =D9/36 -> 16814833 | F9: 사용량비례형 | G9: 100 | H9: 2025-06-26 | I9: 30일 | J9: =M9+O9+Q9+S9+U9+W9+Y9+AA9+AC9+AE9+AG9+AI9+AK9+AM9+AO9+AQ9+AS9+AU9+AW9+AY9+BA9+BC9 -> 1.16296e+08 | K9: =N9+P9+R9+T9+V9+X9+Z9+AB9+AD9+AF9+AH9+AJ9+AL9+AN9+AP9+AR9+AT9+AV9+AX9+AZ9+BB9+BD9 -> 91544000 | L9: =K9/J9 -> 0.78716378 | M9: 0 | N9: 0 | O9: 0 | P9: 0 | Q9: 0 | R9: 0 | S9: 0 | T9: 0 | U9: 0 | V9: 0 | W9: 0 | X9: 0 | Y9: 0 | Z9: 0 | AA9: 0 | AB9: 0 | AC9: 0 | AD9: 0 | AE9: 0 | AF9: 0 | AG9: 0 | AH9: 0 | AI9: 7031000 | AJ9: 0 | AK9: 6773000 | AL9: 0 | AM9: 10192000 | AN9: 0 | AO9: 11258000 | AP9: 13804000 | AQ9: 10855000 | AR9: 10192000 | AS9: 11375000 | AT9: 11258000 | AU9: 12285000 | AV9: 10855000 | AW9: 11791000 | AX9: 11375000 | AY9: 9984000.4 | AZ9: 12285000 | BA9: 12272000 | BB9: 11791000 | BC9: 12480000 | BD9: 9984000
A10: 7 | B10: 10033043 | C10: 메디인병원 | D10: 351426000 | E10: =D10/36 -> 9761833.3 | F10: 사용량비례형 | G10: 30 | H10: 2025-05-29 | I10: 30일 | J10: =M10+O10+Q10+S10+U10+W10+Y10+AA10+AC10+AE10+AG10+AI10+AK10+AM10+AO10+AQ10+AS10+AU10+AW10+AY10+BA10+BC10 -> 89846000 | K10: =N10+P10+R10+T10+V10+X10+Z10+AB10+AD10+AF10+AH10+AJ10+AL10+AN10+AP10+AR10+AT10+AV10+AX10+AZ10+BB10+BD10 -> 78717000 | L10: =K10/J10 -> 0.8761325 | M10: 0 | N10: 0 | O10: 0 | P10: 0 | Q10: 0 | R10: 0 | S10: 0 | T10: 0 | U10: 0 | V10: 0 | W10: 0 | X10: 0 | Y10: 0 | Z10: 0 | AA10: 0 | AB10: 0 | AC10: 0 | AD10: 0 | AE10: 0 | AF10: 0 | AG10: 0 | AH10: 0 | AI10: 0 | AJ10: 0 | AK10: 10003000 | AL10: 0 | AM10: 9494999.8 | AN10: 10003000 | AO10: 6929000.1 | AP10: 9495000 | AQ10: 6105999.9 | AR10: 6929000 | AS10: 8355000.5 | AT10: 6106000 | AU10: 9398999.5 | AV10: 8355000 | AW10: 7645000 | AX10: 9399000 | AY10: 9009999.9 | AZ10: 7645000 | BA10: 11775000 | BB10: 9010000 | BC10: 11129000 | BD10: 11775000
A11: 8 | B11: 10006915 | C11: 해븐리병원 | D11: 1054308548 | E11: =D11/36 -> 29286349 | F11: 사용량비례형 | G11: 117 | H11: 2025-10-23 | I11: 30일 | J11: =M11+O11+Q11+S11+U11+W11+Y11+AA11+AC11+AE11+AG11+AI11+AK11+AM11+AO11+AQ11+AS11+AU11+AW11+AY11+BA11+BC11 -> 83203998 | K11: =N11+P11+R11+T11+V11+X11+Z11+AB11+AD11+AF11+AH11+AJ11+AL11+AN11+AP11+AR11+AT11+AV11+AX11+AZ11+BB11+BD11 -> 75476000 | L11: =K11/J11 -> 0.90711987 | M11: 0 | N11: 0 | O11: 0 | P11: 0 | Q11: 0 | R11: 0 | S11: 0 | T11: 0 | U11: 0 | V11: 0 | W11: 0 | X11: 0 | Y11: 0 | Z11: 0 | AA11: 0 | AB11: 0 | AC11: 0 | AD11: 0 | AE11: 0 | AF11: 0 | AG11: 0 | AH11: 0 | AI11: 0 | AJ11: 0 | AK11: 2692000 | AL11: 0 | AM11: 7072000.1 | AN11: 0 | AO11: 9551999.6 | AP11: 9764000 | AQ11: 8800000 | AR11: 9552000 | AS11: 10080000 | AT11: 8800000 | AU11: 9439999.8 | AV11: 10080000 | AW11: 9695999.5 | AX11: 9440000 | AY11: 9375999.6 | AZ11: 9696000 | BA11: 8768000 | BB11: 9376000 | BC11: 7728000 | BD11: 8768000
A12: 9 | B12: 10033886 | C12: 의료법인우리의료재단 | D12: 1146845000 | E12: =D12/36 -> 31856806 | F12: 사용량비례형 | G12: 241 | H12: 2025-08-28 | I12: 30일 | J12: =M12+O12+Q12+S12+U12+W12+Y12+AA12+AC12+AE12+AG12+AI12+AK12+AM12+AO12+AQ12+AS12+AU12+AW12+AY12+BA12+BC12 -> 5.17049e+08 | K12: =N12+P12+R12+T12+V12+X12+Z12+AB12+AD12+AF12+AH12+AJ12+AL12+AN12+AP12+AR12+AT12+AV12+AX12+AZ12+BB12+BD12 -> 463151000 | L12: =K12/J12 -> 0.89575843 | M12: 0 | N12: 0 | O12: 0 | P12: 0 | Q12: 0 | R12: 0 | S12: 0 | T12: 0 | U12: 0 | V12: 0 | W12: 0 | X12: 0 | Y12: 0 | Z12: 0 | AA12: 0 | AB12: 0 | AC12: 0 | AD12: 0 | AE12: 0 | AF12: 0 | AG12: 0 | AH12: 0 | AI12: 0 | AJ12: 0 | AK12: 82381000 | AL12: 0 | AM12: 39234000 | AN12: 82381000 | AO12: 31564000 | AP12: 39234000 | AQ12: 77142000 | AR12: 31564000 | AS12: 56992000 | AT12: 77142000 | AU12: 35698000 | AV12: 56992000 | AW12: 44343000 | AX12: 35698000 | AY12: 52078000 | AZ12: 44343000 | BA12: 43719000 | BB12: 52078000 | BC12: 53898000 | BD12: 43719000
A13: 10 | B13: 10034115 | C13: 의료법인영문의료재단(다보스) | D13: 420564000 | E13: =D13/36 -> 11682333 | F13: 구독형 | G13: 60 | H13: 2025-09-23 | I13: 0 | J13: =M13+O13+Q13+S13+U13+W13+Y13+AA13+AC13+AE13+AG13+AI13+AK13+AM13+AO13+AQ13+AS13+AU13+AW13+AY13+BA13+BC13 -> 420564000 | K13: =N13+P13+R13+T13+V13+X13+Z13+AB13+AD13+AF13+AH13+AJ13+AL13+AN13+AP13+AR13+AT13+AV13+AX13+AZ13+BB13+BD13 -> 420564000 | L13: =K13/J13 -> 1 | M13: 0 | N13: 0 | O13: 0 | P13: 0 | Q13: 0 | R13: 0 | S13: 0 | T13: 0 | U13: 0 | V13: 0 | W13: 0 | X13: 0 | Y13: 0 | Z13: 0 | AA13: 0 | AB13: 0 | AC13: 0 | AD13: 0 | AE13: 0 | AF13: 0 | AG13: 0 | AH13: 0 | AI13: 420564000 | AJ13: 0 | AK13: 0 | AL13: 0 | AM13: 0 | AN13: 0 | AO13: 0 | AP13: 126169200 | AQ13: 0 | AR13: 294394800 | AS13: 0 | AT13: 0 | AU13: 0 | AV13: 0 | AW13: 0 | AX13: 0 | AY13: 0 | AZ13: 0 | BA13: 0 | BB13: 0 | BC13: 0 | BD13: 0
A14: 11 | B14: 10034679 | C14: 서울성심병원 | D14: 490298000 | E14: =D14/36 -> 13619389 | F14: 사용량비례형 | G14: 80 | H14: 2025-07-07 | I14: 30일 | J14: =M14+O14+Q14+S14+U14+W14+Y14+AA14+AC14+AE14+AG14+AI14+AK14+AM14+AO14+AQ14+AS14+AU14+AW14+AY14+BA14+BC14 -> 1.00027e+08 | K14: =N14+P14+R14+T14+V14+X14+Z14+AB14+AD14+AF14+AH14+AJ14+AL14+AN14+AP14+AR14+AT14+AV14+AX14+AZ14+BB14+BD14 -> 87192000 | L14: =K14/J14 -> 0.87168464 | M14: 0 | N14: 0 | O14: 0 | P14: 0 | Q14: 0 | R14: 0 | S14: 0 | T14: 0 | U14: 0 | V14: 0 | W14: 0 | X14: 0 | Y14: 0 | Z14: 0 | AA14: 0 | AB14: 0 | AC14: 0 | AD14: 0 | AE14: 0 | AF14: 0 | AG14: 0 | AH14: 0 | AI14: 0 | AJ14: 0 | AK14: 7759000 | AL14: 0 | AM14: 12559000 | AN14: 0 | AO14: 9934999.8 | AP14: 20318000 | AQ14: 5438999.5 | AR14: 9935000 | AS14: 10336000 | AT14: 5439000 | AU14: 11513000 | AV14: 10336000 | AW14: 10131000 | AX14: 11513000 | AY14: 9400000.5 | AZ14: 10131000 | BA14: 10120000 | BB14: 9400000 | BC14: 12835000 | BD14: 10120000
A15: 12 | B15: 10044981 | C15: 신일병원 | D15: 404679000 | E15: =D15/36 -> 11241083 | F15: 사용량비례형 | G15: 50 | H15: 2025-07-11 | I15: 30일 | J15: =M15+O15+Q15+S15+U15+W15+Y15+AA15+AC15+AE15+AG15+AI15+AK15+AM15+AO15+AQ15+AS15+AU15+AW15+AY15+BA15+BC15 -> 1.06555e+08 | K15: =N15+P15+R15+T15+V15+X15+Z15+AB15+AD15+AF15+AH15+AJ15+AL15+AN15+AP15+AR15+AT15+AV15+AX15+AZ15+BB15+BD15 -> 95450000 | L15: =K15/J15 -> 0.89578153 | M15: 0 | N15: 0 | O15: 0 | P15: 0 | Q15: 0 | R15: 0 | S15: 0 | T15: 0 | U15: 0 | V15: 0 | W15: 0 | X15: 0 | Y15: 0 | Z15: 0 | AA15: 0 | AB15: 0 | AC15: 0 | AD15: 0 | AE15: 0 | AF15: 0 | AG15: 0 | AH15: 0 | AI15: 0 | AJ15: 0 | AK15: 5964000 | AL15: 0 | AM15: 10713000 | AN15: 0 | AO15: 13101000 | AP15: 5964000 | AQ15: 9824999.8 | AR15: 10713000 | AS15: 12918000 | AT15: 13101000 | AU15: 9395999.8 | AV15: 12743000 | AW15: 9568000.2 | AX15: 14000000 | AY15: 11837000 | AZ15: 14964000 | BA15: 12128000 | BB15: 11837000 | BC15: 11105000 | BD15: 12128000
A16: 13 | B16: 10035069 | C16: 검단탑종합병원 | D16: 1401889000 | E16: =D16/36 -> 38941361 | F16: 사용량비례형 | G16: 280 | H16: 2025-05-20 | I16: 90일 | J16: =M16+O16+Q16+S16+U16+W16+Y16+AA16+AC16+AE16+AG16+AI16+AK16+AM16+AO16+AQ16+AS16+AU16+AW16+AY16+BA16+BC16 -> 4.508744e+08 | K16: =N16+P16+R16+T16+V16+X16+Z16+AB16+AD16+AF16+AH16+AJ16+AL16+AN16+AP16+AR16+AT16+AV16+AX16+AZ16+BB16+BD16 -> 377536400 | L16: =K16/J16 -> 0.83734273 | M16: 0 | N16: 0 | O16: 0 | P16: 0 | Q16: 0 | R16: 0 | S16: 0 | T16: 0 | U16: 0 | V16: 0 | W16: 0 | X16: 0 | Y16: 0 | Z16: 0 | AA16: 0 | AB16: 0 | AC16: 5342000 | AD16: 0 | AE16: 50708800 | AF16: 0 | AG16: 47751600 | AH16: 0 | AI16: 47417200 | AJ16: 0 | AK16: 29072000 | AL16: 103802400 | AM16: 31325200 | AN16: 47417200 | AO16: 20231200 | AP16: 29072000 | AQ16: 23394000 | AR16: 31325200 | AS16: 28542800 | AT16: 0 | AU16: 30392800 | AV16: 43625200 | AW16: 31965200 | AX16: 28542800 | AY16: 31393600 | AZ16: 30392800 | BA16: 37494000 | BB16: 0 | BC16: 35844000 | BD16: 63358800
A17: 14 | B17: 10035078 | C17: 사랑플러스병원 | D17: 279085000 | E17: =D17/36 -> 7752361.1 | F17: 사용량비례형 | G17: 40 | H17: 2025-06-02 | I17: 30일 | J17: =M17+O17+Q17+S17+U17+W17+Y17+AA17+AC17+AE17+AG17+AI17+AK17+AM17+AO17+AQ17+AS17+AU17+AW17+AY17+BA17+BC17 -> 67385999 | K17: =N17+P17+R17+T17+V17+X17+Z17+AB17+AD17+AF17+AH17+AJ17+AL17+AN17+AP17+AR17+AT17+AV17+AX17+AZ17+BB17+BD17 -> 48243000 | L17: =K17/J17 -> 0.71592023 | M17: 0 | N17: 0 | O17: 0 | P17: 0 | Q17: 0 | R17: 0 | S17: 0 | T17: 0 | U17: 0 | V17: 0 | W17: 0 | X17: 0 | Y17: 0 | Z17: 0 | AA17: 0 | AB17: 0 | AC17: 0 | AD17: 0 | AE17: 0 | AF17: 0 | AG17: 0 | AH17: 0 | AI17: 0 | AJ17: 0 | AK17: 2000000 | AL17: 0 | AM17: 6227999.8 | AN17: 0 | AO17: 10475000 | AP17: 0 | AQ17: 9429999.7 | AR17: 0 | AS17: 6361999.6 | AT17: =[1]씽크현황!$AS$18*1000000 -> 28133000 | AU17: 7457000.1 | AV17: 6362000 | AW17: 6291000.1 | AX17: 7457000 | AY17: 7910999.8 | AZ17: 0 | BA17: 5651000 | BB17: 6291000 | BC17: 5581000 | BD17: 0
A18: 15 | B18: 10046570 | C18: 의료법인성지의료재단(성지병원) | D18: 884442000 | E18: =D18/36 -> 24567833 | F18: 사용량비례형 | G18: 130 | H18: 2025-09-02 | I18: 30일 | J18: =M18+O18+Q18+S18+U18+W18+Y18+AA18+AC18+AE18+AG18+AI18+AK18+AM18+AO18+AQ18+AS18+AU18+AW18+AY18+BA18+BC18 -> 2.05374e+08 | K18: =N18+P18+R18+T18+V18+X18+Z18+AB18+AD18+AF18+AH18+AJ18+AL18+AN18+AP18+AR18+AT18+AV18+AX18+AZ18+BB18+BD18 -> 160992000 | L18: =K18/J18 -> 0.78389669 | M18: 0 | N18: 0 | O18: 0 | P18: 0 | Q18: 0 | R18: 0 | S18: 0 | T18: 0 | U18: 0 | V18: 0 | W18: 0 | X18: 0 | Y18: 0 | Z18: 0 | AA18: 0 | AB18: 0 | AC18: 0 | AD18: 0 | AE18: 0 | AF18: 0 | AG18: 0 | AH18: 0 | AI18: 0 | AJ18: 0 | AK18: 3042000 | AL18: 0 | AM18: 20618000 | AN18: 3042000 | AO18: 27495000 | AP18: 3042000 | AQ18: 17095000 | AR18: 20618000 | AS18: 21021000 | AT18: 27495000 | AU18: 20384000 | AV18: 17095000 | AW18: 24089000 | AX18: 21021000 | AY18: 24206000 | AZ18: 20384000 | BA18: 25701000 | BB18: 24089000 | BC18: 21723000 | BD18: 24206000
A19: 16 | B19: 10036016 | C19: 시원병원 | D19: 324592000 | E19: =D19/36 -> 9016444.4 | F19: 사용량비례형 | G19: 30 | H19: 2025-08-11 | I19: 30일 | J19: =M19+O19+Q19+S19+U19+W19+Y19+AA19+AC19+AE19+AG19+AI19+AK19+AM19+AO19+AQ19+AS19+AU19+AW19+AY19+BA19+BC19 -> 37423999 | K19: =N19+P19+R19+T19+V19+X19+Z19+AB19+AD19+AF19+AH19+AJ19+AL19+AN19+AP19+AR19+AT19+AV19+AX19+AZ19+BB19+BD19 -> 34224000 | L19: =K19/J19 -> 0.9144934 | M19: 0 | N19: 0 | O19: 0 | P19: 0 | Q19: 0 | R19: 0 | S19: 0 | T19: 0 | U19: 0 | V19: 0 | W19: 0 | X19: 0 | Y19: 0 | Z19: 0 | AA19: 0 | AB19: 0 | AC19: 0 | AD19: 0 | AE19: 0 | AF19: 0 | AG19: 0 | AH19: 0 | AI19: 0 | AJ19: 0 | AK19: 1328000 | AL19: 0 | AM19: 5056000.4 | AN19: 1328000 | AO19: 3215999.6 | AP19: 5056000 | AQ19: 4591999.5 | AR19: 3216000 | AS19: 5951999.9 | AT19: 4592000 | AU19: 2880000.2 | AV19: 5952000 | AW19: 2431999.9 | AX19: 2880000.2 | AY19: 5119999.5 | AZ19: 2432000 | BA19: 3648000 | BB19: 5120000 | BC19: 3200000 | BD19: 3648000
A20: 17 | B20: 10036590 | C20: 당진종합병원 | D20: 969531000 | E20: =D20/36 -> 26931417 | F20: 사용량비례형 | G20: 160 | H20: 2025-06-30 | I20: 40일 | J20: =M20+O20+Q20+S20+U20+W20+Y20+AA20+AC20+AE20+AG20+AI20+AK20+AM20+AO20+AQ20+AS20+AU20+AW20+AY20+BA20+BC20 -> 2.11737e+08 | K20: =N20+P20+R20+T20+V20+X20+Z20+AB20+AD20+AF20+AH20+AJ20+AL20+AN20+AP20+AR20+AT20+AV20+AX20+AZ20+BB20+BD20 -> 133032000 | L20: =K20/J20 -> 0.62828887 | M20: 0 | N20: 0 | O20: 0 | P20: 0 | Q20: 0 | R20: 0 | S20: 0 | T20: 0 | U20: 0 | V20: 0 | W20: 0 | X20: 0 | Y20: 0 | Z20: 0 | AA20: 0 | AB20: 0 | AC20: 0 | AD20: 0 | AE20: 0 | AF20: 0 | AG20: 0 | AH20: 0 | AI20: 0 | AJ20: 0 | AK20: 7696000 | AL20: 0 | AM20: 13883000 | AN20: 0 | AO20: 13752000 | AP20: 7696000 | AQ20: 8216000.1 | AR20: 14135000 | AS20: 12259000 | AT20: 14004000 | AU20: 19387000 | AV20: 8216000 | AW20: 28381000 | AX20: 11755000 | AY20: 29458000 | AZ20: 19387000 | BA20: 27190000 | BB20: 28381000 | BC20: 51515000 | BD20: 29458000
A21: 18 | B21: 10008171 | C21: 현대병원 | D21: 476620000 | E21: =D21/36 -> 13239444 | F21: 사용량비례형 | G21: 84 | H21: 2025-06-25 | I21: 30일 | J21: =M21+O21+Q21+S21+U21+W21+Y21+AA21+AC21+AE21+AG21+AI21+AK21+AM21+AO21+AQ21+AS21+AU21+AW21+AY21+BA21+BC21 -> 1.43894e+08 | K21: =N21+P21+R21+T21+V21+X21+Z21+AB21+AD21+AF21+AH21+AJ21+AL21+AN21+AP21+AR21+AT21+AV21+AX21+AZ21+BB21+BD21 -> 43033000 | L21: =K21/J21 -> 0.29906042 | M21: 0 | N21: 0 | O21: 0 | P21: 0 | Q21: 0 | R21: 0 | S21: 0 | T21: 0 | U21: 0 | V21: 0 | W21: 0 | X21: 0 | Y21: 0 | Z21: 0 | AA21: 0 | AB21: 0 | AC21: 0 | AD21: 0 | AE21: 0 | AF21: 0 | AG21: 0 | AH21: 0 | AI21: 0 | AJ21: 0 | AK21: 2649000 | AL21: 0 | AM21: 7051000 | AN21: 0 | AO21: 15753000 | AP21: 0 | AQ21: 17760000 | AR21: 9700000 | AS21: 18561000 | AT21: 0 | AU21: 13519000 | AV21: 0 | AW21: 17250000 | AX21: 0 | AY21: 14896000 | AZ21: 0 | BA21: 15462000 | BB21: 15573000 | BC21: 20993000 | BD21: 17760000
A22: 19 | B22: 10037290 | C22: 이화의대부속서울병원 | D22: 220000000 | E22: =D22/36 -> 6111111.1 | F22: 구축형 | G22: 30 | H22: 2025 4Q | I22: 25.12.31 | J22: =M22+O22+Q22+S22+U22+W22+Y22+AA22+AC22+AE22+AG22+AI22+AK22+AM22+AO22+AQ22+AS22+AU22+AW22+AY22+BA22+BC22 -> 220000000 | K22: =N22+P22+R22+T22+V22+X22+Z22+AB22+AD22+AF22+AH22+AJ22+AL22+AN22+AP22+AR22+AT22+AV22+AX22+AZ22+BB22+BD22 -> 220000000 | L22: =K22/J22 -> 1 | M22: 0 | N22: 0 | O22: 0 | P22: 0 | Q22: 0 | R22: 0 | S22: 0 | T22: 0 | U22: 0 | V22: 0 | W22: 0 | X22: 0 | Y22: 0 | Z22: 0 | AA22: 0 | AB22: 0 | AC22: 0 | AD22: 0 | AE22: 220000000 | AF22: 0 | AG22: 0 | AH22: 0 | AI22: 0 | AJ22: 0 | AK22: -220000000 | AL22: 0 | AM22: 220000000 | AN22: 0 | AO22: 0 | AP22: 220000000 | AQ22: 0 | AR22: 0 | AS22: 0 | AT22: 0 | AU22: 0 | AV22: 0 | AW22: 0 | AX22: 0 | AY22: 0 | AZ22: 0 | BA22: 0 | BB22: 0 | BC22: 0 | BD22: 0
A23: 20 | B23: 10037788 | C23: 부안성모병원 | D23: 209165000 | E23: =D23/36 -> 5810138.9 | F23: 분납형 | G23: 44 | H23: 2025-09-08 | I23: 30일 | J23: =M23+O23+Q23+S23+U23+W23+Y23+AA23+AC23+AE23+AG23+AI23+AK23+AM23+AO23+AQ23+AS23+AU23+AW23+AY23+BA23+BC23 -> 209165000 | K23: =N23+P23+R23+T23+V23+X23+Z23+AB23+AD23+AF23+AH23+AJ23+AL23+AN23+AP23+AR23+AT23+AV23+AX23+AZ23+BB23+BD23 -> 209165000 | L23: =K23/J23 -> 1 | M23: 0 | N23: 0 | O23: 0 | P23: 0 | Q23: 0 | R23: 0 | S23: 0 | T23: 0 | U23: 0 | V23: 0 | W23: 0 | X23: 0 | Y23: 0 | Z23: 0 | AA23: 0 | AB23: 0 | AC23: 0 | AD23: 0 | AE23: 0 | AF23: 0 | AG23: 0 | AH23: 0 | AI23: 0 | AJ23: 0 | AK23: 209165000 | AL23: 0 | AM23: 0 | AN23: 69165000 | AO23: 0 | AP23: 70000000 | AQ23: 0 | AR23: 70000000 | AS23: 0 | AT23: 0 | AU23: 0 | AV23: 0 | AW23: 0 | AX23: 0 | AY23: 0 | AZ23: 0 | BA23: 0 | BB23: 0 | BC23: 0 | BD23: 0
A24: 21 | B24: 10038346 | C24: 목포기독병원 | D24: 1600698000 | E24: =D24/36 -> 44463833 | F24: 사용량비례형 | G24: 280 | H24: 2025-06-17 | I24: 30일 | J24: =M24+O24+Q24+S24+U24+W24+Y24+AA24+AC24+AE24+AG24+AI24+AK24+AM24+AO24+AQ24+AS24+AU24+AW24+AY24+BA24+BC24 -> 180983000 | K24: =N24+P24+R24+T24+V24+X24+Z24+AB24+AD24+AF24+AH24+AJ24+AL24+AN24+AP24+AR24+AT24+AV24+AX24+AZ24+BB24+BD24 -> 161305000 | L24: =K24/J24 -> 0.89127156 | M24: 0 | N24: 0 | O24: 0 | P24: 0 | Q24: 0 | R24: 0 | S24: 0 | T24: 0 | U24: 0 | V24: 0 | W24: 0 | X24: 0 | Y24: 0 | Z24: 0 | AA24: 0 | AB24: 0 | AC24: 0 | AD24: 0 | AE24: 0 | AF24: 0 | AG24: 328000 | AH24: 0 | AI24: 0 | AJ24: 0 | AK24: 2789000 | AL24: 0 | AM24: 14000000 | AN24: 0 | AO24: 16332000 | AP24: 3117000 | AQ24: 26378000 | AR24: 24332000 | AS24: 23126000 | AT24: 29378000 | AU24: 20658000 | AV24: 26126000 | AW24: 19804000 | AX24: 20658000 | AY24: 17851000 | AZ24: 19804000 | BA24: 20039000 | BB24: 17851000 | BC24: 19678000 | BD24: 20039000
A25: 22 | B25: 10039242 | C25: 수성한미병원 | D25: 254146000 | E25: =D25/36 -> 7059611.1 | F25: 사용량비례형 | G25: 30 | H25: 2025-07-16 | I25: 30일 | J25: =M25+O25+Q25+S25+U25+W25+Y25+AA25+AC25+AE25+AG25+AI25+AK25+AM25+AO25+AQ25+AS25+AU25+AW25+AY25+BA25+BC25 -> 47931999 | K25: =N25+P25+R25+T25+V25+X25+Z25+AB25+AD25+AF25+AH25+AJ25+AL25+AN25+AP25+AR25+AT25+AV25+AX25+AZ25+BB25+BD25 -> 42120000 | L25: =K25/J25 -> 0.8787449 | M25: 0 | N25: 0 | O25: 0 | P25: 0 | Q25: 0 | R25: 0 | S25: 0 | T25: 0 | U25: 0 | V25: 0 | W25: 0 | X25: 0 | Y25: 0 | Z25: 0 | AA25: 0 | AB25: 0 | AC25: 0 | AD25: 0 | AE25: 0 | AF25: 0 | AG25: 0 | AH25: 0 | AI25: 0 | AJ25: 0 | AK25: 1668000 | AL25: 0 | AM25: 4210000.3 | AN25: 1668000 | AO25: 5992000.3 | AP25: 0 | AQ25: 4270999.7 | AR25: 10202000 | AS25: 5062999.7 | AT25: 4271000 | AU25: 4653999.9 | AV25: 5063000 | AW25: 4380999.7 | AX25: 4654000 | AY25: 5811999.6 | AZ25: 4381000 | BA25: 6069000 | BB25: 5812000 | BC25: 5812000 | BD25: 6069000
A26: 23 | B26: 10039905 | C26: 카톨릭병원(대구) | D26: 137000000 | E26: =D26/36 -> 3805555.6 | F26: 구축형 | G26: 20 | H26: 2025-09-16 | I26: 통살적 결제조건 | J26: =M26+O26+Q26+S26+U26+W26+Y26+AA26+AC26+AE26+AG26+AI26+AK26+AM26+AO26+AQ26+AS26+AU26+AW26+AY26+BA26+BC26 -> 137000000 | K26: =N26+P26+R26+T26+V26+X26+Z26+AB26+AD26+AF26+AH26+AJ26+AL26+AN26+AP26+AR26+AT26+AV26+AX26+AZ26+BB26+BD26 -> 137000000 | L26: =K26/J26 -> 1 | M26: 0 | N26: 0 | O26: 0 | P26: 0 | Q26: 0 | R26: 0 | S26: 0 | T26: 0 | U26: 0 | V26: 0 | W26: 0 | X26: 0 | Y26: 0 | Z26: 0 | AA26: 0 | AB26: 0 | AC26: 0 | AD26: 0 | AE26: 0 | AF26: 0 | AG26: 0 | AH26: 0 | AI26: 0 | AJ26: 0 | AK26: 137000000 | AL26: 0 | AM26: 0 | AN26: 0 | AO26: 0 | AP26: 0 | AQ26: 0 | AR26: 0 | AS26: 0 | AT26: 137000000 | AU26: 0 | AV26: 0 | AW26: 0 | AX26: 0 | AY26: 0 | AZ26: 0 | BA26: 0 | BB26: 0 | BC26: 0 | BD26: 0
A27: 24 | B27: 10003599 | C27: 의료법인온그룹의료재단온종합병원 | D27: 272046000 | E27: =D27/36 -> 7556833.3 | F27: 사용량비례형 | G27: 39 | H27: 2025-06-30 | I27: 30일 | J27: =M27+O27+Q27+S27+U27+W27+Y27+AA27+AC27+AE27+AG27+AI27+AK27+AM27+AO27+AQ27+AS27+AU27+AW27+AY27+BA27+BC27 -> 72696000 | K27: =N27+P27+R27+T27+V27+X27+Z27+AB27+AD27+AF27+AH27+AJ27+AL27+AN27+AP27+AR27+AT27+AV27+AX27+AZ27+BB27+BD27 -> 51350000 | L27: =K27/J27 -> 0.70636623 | M27: 0 | N27: 0 | O27: 0 | P27: 0 | Q27: 0 | R27: 0 | S27: 0 | T27: 0 | U27: 0 | V27: 0 | W27: 0 | X27: 0 | Y27: 0 | Z27: 0 | AA27: 0 | AB27: 0 | AC27: 0 | AD27: 0 | AE27: 0 | AF27: 0 | AG27: 0 | AH27: 0 | AI27: 1180000 | AJ27: 0 | AK27: 0 | AL27: 0 | AM27: 9262000 | AN27: 0 | AO27: 13878000 | AP27: 0 | AQ27: 12687000 | AR27: 0 | AS27: 13422000 | AT27: 1179999.7 | AU27: 14279000 | AV27: 0 | AW27: 2200000 | AX27: 0 | AY27: -15558000 | AZ27: 0 | BA27: 14431000 | BB27: 50170000 | BC27: 6915000 | BD27: 0
A28: 25 | B28: 10041502 | C28: 한라의료원 | D28: 2922731000 | E28: =D28/36 -> 81186972 | F28: 사용량비례형 | G28: 500 | H28: 2025-06-27 | I28: 60일 | J28: =M28+O28+Q28+S28+U28+W28+Y28+AA28+AC28+AE28+AG28+AI28+AK28+AM28+AO28+AQ28+AS28+AU28+AW28+AY28+BA28+BC28 -> 2.76229e+08 | K28: =N28+P28+R28+T28+V28+X28+Z28+AB28+AD28+AF28+AH28+AJ28+AL28+AN28+AP28+AR28+AT28+AV28+AX28+AZ28+BB28+BD28 -> 221341000 | L28: =K28/J28 -> 0.8012953 | M28: 0 | N28: 0 | O28: 0 | P28: 0 | Q28: 0 | R28: 0 | S28: 0 | T28: 0 | U28: 0 | V28: 0 | W28: 0 | X28: 0 | Y28: 0 | Z28: 0 | AA28: 0 | AB28: 0 | AC28: 0 | AD28: 0 | AE28: 0 | AF28: 0 | AG28: 0 | AH28: 0 | AI28: 0 | AJ28: 0 | AK28: 26249000 | AL28: 0 | AM28: 31023000 | AN28: 0 | AO28: 32760000 | AP28: 26249000 | AQ28: 24085000 | AR28: 0 | AS28: 28278000 | AT28: 31023000 | AU28: 25000000 | AV28: 32760000 | AW28: 25000000 | AX28: 0 | AY28: 28946000 | AZ28: 102363000 | BA28: 27334000 | BB28: 28946000 | BC28: 27554000 | BD28: 0
A29: 26 | B29: 10047292 | C29: 의료법인숭인의료재단김해복음병원 | D29: 1705382900 | E29: =D29/36 -> 47371747 | F29: 사용량비례형 | G29: 200 | H29: 2025-08-28 | I29: 30일 | J29: =M29+O29+Q29+S29+U29+W29+Y29+AA29+AC29+AE29+AG29+AI29+AK29+AM29+AO29+AQ29+AS29+AU29+AW29+AY29+BA29+BC29 -> 3.20949e+08 | K29: =N29+P29+R29+T29+V29+X29+Z29+AB29+AD29+AF29+AH29+AJ29+AL29+AN29+AP29+AR29+AT29+AV29+AX29+AZ29+BB29+BD29 -> 108829000 | L29: =K29/J29 -> 0.33908503 | M29: 0 | N29: 0 | O29: 0 | P29: 0 | Q29: 0 | R29: 0 | S29: 0 | T29: 0 | U29: 0 | V29: 0 | W29: 0 | X29: 0 | Y29: 0 | Z29: 0 | AA29: 0 | AB29: 0 | AC29: 0 | AD29: 0 | AE29: 0 | AF29: 0 | AG29: 0 | AH29: 0 | AI29: 0 | AJ29: 0 | AK29: 766000 | AL29: 0 | AM29: 20672000 | AN29: 0 | AO29: 26343000 | AP29: 0 | AQ29: 27209000 | AR29: 0 | AS29: 34560000 | AT29: 0 | AU29: 33868000 | AV29: 20717000 | AW29: 44222000 | AX29: 0 | AY29: 47991000 | AZ29: 0 | BA29: 43419000 | BB29: 53552000 | BC29: 41899000 | BD29: 34560000
... A40: 37 | B40: 10041592 | C40: 비에이치에스한서병원 | D40: 1474061000 | E40: =D40/36 -> 40946139 | F40: 사용량비례형 | G40: 50 | H40: 2025-05-28 | I40: 30일 | J40: =M40+O40+Q40+S40+U40+W40+Y40+AA40+AC40+AE40+AG40+AI40+AK40+AM40+AO40+AQ40+AS40+AU40+AW40+AY40+BA40+BC40 -> 4.1656e+08 | K40: =N40+P40+R40+T40+V40+X40+Z40+AB40+AD40+AF40+AH40+AJ40+AL40+AN40+AP40+AR40+AT40+AV40+AX40+AZ40+BB40+BD40 -> 416152000 | L40: =K40/J40 -> 0.99902055 | M40: 0 | N40: 0 | O40: 0 | P40: 0 | Q40: 0 | R40: 0 | S40: 0 | T40: 0 | U40: 0 | V40: 0 | W40: 0 | X40: 0 | Y40: 0 | Z40: 0 | AA40: 0 | AB40: 0 | AC40: 0 | AD40: 0 | AE40: 2251000 | AF40: 0 | AG40: 12500000 | AH40: 2251000 | AI40: 12500000 | AJ40: 12500000 | AK40: 18531000 | AL40: 12500000 | AM40: 33980000 | AN40: 18531000 | AO40: 41768000 | AP40: 33980000 | AQ40: 46084000 | AR40: 41768000 | AS40: 49624000 | AT40: 46084000 | AU40: 49379000 | AV40: 49624000 | AW40: 52024000 | AX40: 49379000 | AY40: 48231000 | AZ40: 52024000 | BA40: 49280000 | BB40: 48231000 | BC40: 408000 | BD40: 49280000
A41: 38 | B41: 10112765 | C41: 의료법인라움의료재단세웅병원 (구. 10041888) | D41: 436766000 | E41: =D41/36 -> 12132389 | F41: 사용량비례형 | G41: 50 | H41: 2025-09-26 | J41: =M41+O41+Q41+S41+U41+W41+Y41+AA41+AC41+AE41+AG41+AI41+AK41+AM41+AO41+AQ41+AS41+AU41+AW41+AY41+BA41+BC41 -> 3.59531e+08 | K41: =N41+P41+R41+T41+V41+X41+Z41+AB41+AD41+AF41+AH41+AJ41+AL41+AN41+AP41+AR41+AT41+AV41+AX41+AZ41+BB41+BD41 -> 193319000 | L41: =K41/J41 -> 0.53769772 | M41: 0 | N41: 0 | O41: 0 | P41: 0 | Q41: 0 | R41: 0 | S41: 0 | T41: 0 | U41: 0 | V41: 0 | W41: 0 | X41: 0 | Y41: 0 | Z41: 0 | AA41: 0 | AB41: 0 | AC41: 0 | AD41: 0 | AE41: 9332000 | AF41: 0 | AG41: 0 | AH41: 0 | AI41: 36520000 | AJ41: 9332000 | AK41: 22880000 | AL41: 18685000 | AM41: 31550000 | AN41: 17835000 | AO41: 31562000 | AP41: 22880000 | AQ41: 28579000 | AR41: 31550000 | AS41: 32896000 | AT41: 31562000 | AU41: 0 | AV41: 61475000 | AW41: 0 | AX41: 0 | AY41: 71927000 | AZ41: 0 | BA41: 75658000 | BB41: 0 | BC41: 18627000 | BD41: 0
A42: 39 | B42: 10047340 | C42: 시영의료재단영동병원 | D42: 259531000 | E42: =D42/36 -> 7209194.4 | F42: 구축형 | G42: 40 | H42: 2025-09-03 | I42: 30일 | J42: =M42+O42+Q42+S42+U42+W42+Y42+AA42+AC42+AE42+AG42+AI42+AK42+AM42+AO42+AQ42+AS42+AU42+AW42+AY42+BA42+BC42 -> 259531000 | K42: =N42+P42+R42+T42+V42+X42+Z42+AB42+AD42+AF42+AH42+AJ42+AL42+AN42+AP42+AR42+AT42+AV42+AX42+AZ42+BB42+BD42 -> 259531000 | L42: =K42/J42 -> 1 | M42: 0 | N42: 0 | O42: 0 | P42: 0 | Q42: 0 | R42: 0 | S42: 0 | T42: 0 | U42: 0 | V42: 0 | W42: 0 | X42: 0 | Y42: 0 | Z42: 0 | AA42: 0 | AB42: 0 | AC42: 0 | AD42: 0 | AE42: 0 | AF42: 0 | AG42: 259531000 | AH42: 0 | AI42: 0 | AJ42: 0 | AK42: 0 | AL42: 159531000 | AM42: 0 | AN42: 100000000 | AO42: 0 | AP42: 0 | AQ42: 0 | AR42: 0 | AS42: 0 | AT42: 0 | AU42: 0 | AV42: 0 | AW42: 0 | AX42: 0 | AY42: 0 | AZ42: 0 | BA42: 0 | BB42: 0 | BC42: 0 | BD42: 0
A43: 40 | B43: 10040545 | C43: 부산본병원 | D43: 251823000 | E43: =D43/36 -> 6995083.3 | F43: 사용량비례형 | G43: 30 | H43: 2025-07-15 | I43: 30일 | J43: =M43+O43+Q43+S43+U43+W43+Y43+AA43+AC43+AE43+AG43+AI43+AK43+AM43+AO43+AQ43+AS43+AU43+AW43+AY43+BA43+BC43 -> 1.07609e+08 | K43: =N43+P43+R43+T43+V43+X43+Z43+AB43+AD43+AF43+AH43+AJ43+AL43+AN43+AP43+AR43+AT43+AV43+AX43+AZ43+BB43+BD43 -> 100438464 | L43: =K43/J43 -> 0.9333649 | M43: 0 | N43: 0 | O43: 0 | P43: 0 | Q43: 0 | R43: 0 | S43: 0 | T43: 0 | U43: 0 | V43: 0 | W43: 0 | X43: 0 | Y43: 0 | Z43: 0 | AA43: 0 | AB43: 0 | AC43: 0 | AD43: 0 | AE43: 0 | AF43: 0 | AG43: 6567000 | AH43: 0 | AI43: 11123000 | AJ43: 6567000 | AK43: 10490000 | AL43: 11123000 | AM43: 9615999.8 | AN43: 10490000 | AO43: 8770999.6 | AP43: 9616000 | AQ43: 8019999.9 | AR43: 8771000 | AS43: 10885000 | AT43: 8020000 | AU43: 10085000 | AV43: 11132464 | AW43: 7585000.5 | AX43: 10085000 | AY43: 8259000.2 | AZ43: 7585000 | BA43: 8790000 | BB43: 8259000 | BC43: 7418000 | BD43: 8790000
A44: 41 | B44: 10033733 | C44: 의료법인효심의료재단(용인서울병원) | D44: 190000000 | E44: =D44/36 -> 5277777.8 | F44: 구독형 | G44: 30 | H44: 2025-04-23 | I44: 0 | J44: =M44+O44+Q44+S44+U44+W44+Y44+AA44+AC44+AE44+AG44+AI44+AK44+AM44+AO44+AQ44+AS44+AU44+AW44+AY44+BA44+BC44 -> 190000000 | K44: =N44+P44+R44+T44+V44+X44+Z44+AB44+AD44+AF44+AH44+AJ44+AL44+AN44+AP44+AR44+AT44+AV44+AX44+AZ44+BB44+BD44 -> 190000000 | L44: =K44/J44 -> 1 | M44: 0 | N44: 0 | O44: 0 | P44: 0 | Q44: 0 | R44: 0 | S44: 0 | T44: 0 | U44: 0 | V44: 0 | W44: 190000000 | X44: 0 | Y44: 0 | Z44: 0 | AA44: 0 | AB44: 0 | AC44: 0 | AD44: 0 | AE44: 0 | AF44: 0 | AG44: 0 | AH44: 20000000 | AI44: 0 | AJ44: 50000000 | AK44: 0 | AL44: 50000000 | AM44: 0 | AN44: 50000000 | AO44: 0 | AP44: 20000000 | AQ44: 0 | AR44: 0 | AS44: 0 | AT44: 0 | AU44: 0 | AV44: 0 | AW44: 0 | AX44: 0 | AY44: 0 | AZ44: 0 | BA44: 0 | BB44: 0 | BC44: 0 | BD44: 0
A45: 42 | B45: 10039216 | C45: 의료법인춘곡의료재단 | D45: 164163000 | E45: =D45/36 -> 4560083.3 | F45: 구축형 | G45: 20 | H45: 2025-06-09 | I45: 180일 | J45: =M45+O45+Q45+S45+U45+W45+Y45+AA45+AC45+AE45+AG45+AI45+AK45+AM45+AO45+AQ45+AS45+AU45+AW45+AY45+BA45+BC45 -> 164163000 | K45: =N45+P45+R45+T45+V45+X45+Z45+AB45+AD45+AF45+AH45+AJ45+AL45+AN45+AP45+AR45+AT45+AV45+AX45+AZ45+BB45+BD45 -> 164163000 | L45: =K45/J45 -> 1 | M45: 0 | N45: 0 | O45: 0 | P45: 0 | Q45: 0 | R45: 0 | S45: 0 | T45: 0 | U45: 0 | V45: 0 | W45: 0 | X45: 0 | Y45: 164163000 | Z45: 0 | AA45: 0 | AB45: 0 | AC45: 0 | AD45: 0 | AE45: 0 | AF45: 27360500 | AG45: 0 | AH45: 27360500 | AI45: 0 | AJ45: 27360500 | AK45: 0 | AL45: 27360500 | AM45: 0 | AN45: 54721000 | AO45: 0 | AP45: 0 | AQ45: 0 | AR45: 0 | AS45: 0 | AT45: 0 | AU45: 0 | AV45: 0 | AW45: 0 | AX45: 0 | AY45: 0 | AZ45: 0 | BA45: 0 | BB45: 0 | BC45: 0 | BD45: 0
A46: 43 | B46: 10037883 | C46: 화순성심병원 | D46: 936980000 | E46: =D46/36 -> 26027222 | F46: 사용량비례형 | G46: 150 | H46: 2025-05-28 | I46: 30일 | J46: =M46+O46+Q46+S46+U46+W46+Y46+AA46+AC46+AE46+AG46+AI46+AK46+AM46+AO46+AQ46+AS46+AU46+AW46+AY46+BA46+BC46 -> 339951001 | K46: =N46+P46+R46+T46+V46+X46+Z46+AB46+AD46+AF46+AH46+AJ46+AL46+AN46+AP46+AR46+AT46+AV46+AX46+AZ46+BB46+BD46 -> 319026000 | L46: =K46/J46 -> 0.93844701 | M46: 0 | N46: 0 | O46: 0 | P46: 0 | Q46: 0 | R46: 0 | S46: 0 | T46: 0 | U46: 0 | V46: 0 | W46: 0 | X46: 0 | Y46: 0 | Z46: 0 | AA46: 0 | AB46: 0 | AC46: 0 | AD46: 0 | AE46: 0 | AF46: 0 | AG46: 25390000 | AH46: 0 | AI46: 32179000 | AJ46: 25390000 | AK46: 28493000 | AL46: 32179000 | AM46: 39226000 | AN46: 28493000 | AO46: 36939000 | AP46: 39226000 | AQ46: 29843000 | AR46: 36939000 | AS46: 36473000 | AT46: 29843000 | AU46: 24317000 | AV46: 36473000 | AW46: 24737000 | AX46: 24317000 | AY46: 20447000 | AZ46: 24737000 | BA46: 20982000 | BB46: 20982000 | BC46: 20925000 | BD46: 20447000
A47: 44 | B47: 10036633 | C47: 예산명지병원 | D47: 611986000 | E47: =D47/36 -> 16999611 | F47: 사용량비례형 | G47: 100 | H47: 2025-05-26 | I47: 30일 | J47: =M47+O47+Q47+S47+U47+W47+Y47+AA47+AC47+AE47+AG47+AI47+AK47+AM47+AO47+AQ47+AS47+AU47+AW47+AY47+BA47+BC47 -> 1.89623e+08 | K47: =N47+P47+R47+T47+V47+X47+Z47+AB47+AD47+AF47+AH47+AJ47+AL47+AN47+AP47+AR47+AT47+AV47+AX47+AZ47+BB47+BD47 -> 169647000 | L47: =K47/J47 -> 0.89465413 | M47: 0 | N47: 0 | O47: 0 | P47: 0 | Q47: 0 | R47: 0 | S47: 0 | T47: 0 | U47: 0 | V47: 0 | W47: 0 | X47: 0 | Y47: 0 | Z47: 0 | AA47: 0 | AB47: 0 | AC47: 4505000 | AD47: 0 | AE47: 20613000 | AF47: 4505000 | AG47: 16273000 | AH47: 10613000 | AI47: 20004000 | AJ47: 10000000 | AK47: 23364000 | AL47: 36277000 | AM47: 21445000 | AN47: 10000000 | AO47: 13562000 | AP47: 18364000 | AQ47: 12346000 | AR47: 21897000 | AS47: 8754000.2 | AT47: 15276000 | AU47: 7634999.9 | AV47: 9000000 | AW47: 9573999.6 | AX47: 8934000 | AY47: 8571999.7 | AZ47: 8209000 | BA47: 11705000 | BB47: 13572000 | BC47: 11271000 | BD47: 3000000
A48: 45 | B48: 10070268 | C48: 천안리턴병원 | D48: 632326000 | E48: =D48/36 -> 17564611 | F48: 사용량비례형 | G48: 110 | H48: 2025-05-20 | I48: 30일 | J48: =M48+O48+Q48+S48+U48+W48+Y48+AA48+AC48+AE48+AG48+AI48+AK48+AM48+AO48+AQ48+AS48+AU48+AW48+AY48+BA48+BC48 -> 1.68896e+08 | K48: =N48+P48+R48+T48+V48+X48+Z48+AB48+AD48+AF48+AH48+AJ48+AL48+AN48+AP48+AR48+AT48+AV48+AX48+AZ48+BB48+BD48 -> 153472000 | L48: =K48/J48 -> 0.90867753 | M48: 0 | N48: 0 | O48: 0 | P48: 0 | Q48: 0 | R48: 0 | S48: 0 | T48: 0 | U48: 0 | V48: 0 | W48: 0 | X48: 0 | Y48: 0 | Z48: 0 | AA48: 0 | AB48: 0 | AC48: 0 | AD48: 0 | AE48: 8893000 | AF48: 0 | AG48: 10776000 | AH48: 8893000 | AI48: 12637000 | AJ48: 10776000 | AK48: 11348000 | AL48: 12637000 | AM48: 12920000 | AN48: 11348000 | AO48: 11738000 | AP48: 12920000 | AQ48: 11268000 | AR48: 11738000 | AS48: 12484000 | AT48: 11268000 | AU48: 12318000 | AV48: 12484000 | AW48: 13783000 | AX48: 12318000 | AY48: 16248000 | AZ48: 13783000 | BA48: 19059000 | BB48: 16248000 | BC48: 15424000 | BD48: 19059000
A49: 46 | B49: 10032935 | C49: 추병원 | D49: 1141151000 | E49: =D49/36 -> 31698639 | F49: 사용량비례형 | G49: 169 | H49: 2025-07-11 | I49: 30일 | J49: =M49+O49+Q49+S49+U49+W49+Y49+AA49+AC49+AE49+AG49+AI49+AK49+AM49+AO49+AQ49+AS49+AU49+AW49+AY49+BA49+BC49 -> 4.73303e+08 | K49: =N49+P49+R49+T49+V49+X49+Z49+AB49+AD49+AF49+AH49+AJ49+AL49+AN49+AP49+AR49+AT49+AV49+AX49+AZ49+BB49+BD49 -> 404855000 | L49: =K49/J49 -> 0.85538228 | M49: 0 | N49: 0 | O49: 0 | P49: 0 | Q49: 0 | R49: 0 | S49: 0 | T49: 0 | U49: 0 | V49: 0 | W49: 0 | X49: 0 | Y49: 0 | Z49: 0 | AA49: 0 | AB49: 0 | AC49: 0 | AD49: 0 | AE49: 52158000 | AF49: 0 | AG49: 45991000 | AH49: 52158000 | AI49: 39868000 | AJ49: 52158000 | AK49: 40104000 | AL49: 0 | AM49: 47039000 | AN49: 33701000 | AO49: 38784000 | AP49: 40104000 | AQ49: 37246000 | AR49: 47039000 | AS49: 38305000 | AT49: 38784000 | AU49: 23680000 | AV49: 37246000 | AW49: 21712000 | AX49: 38305000 | AY49: 19968000 | AZ49: 23680000 | BA49: 34368000 | BB49: 21712000 | BC49: 34080000 | BD49: 19968000
A50: 47-1 | B50: 10003837 | C50: 빌리브세웅병원 | D50: 125000000 | E50: =D50/36 -> 3472222.2 | F50: 구독형 | G50: 10 | H50: 2025-04-01 | I50: 30일 | J50: =M50+O50+Q50+S50+U50+W50+Y50+AA50+AC50+AE50+AG50+AI50+AK50+AM50+AO50+AQ50+AS50+AU50+AW50+AY50+BA50+BC50 -> 125000000 | K50: =N50+P50+R50+T50+V50+X50+Z50+AB50+AD50+AF50+AH50+AJ50+AL50+AN50+AP50+AR50+AT50+AV50+AX50+AZ50+BB50+BD50 -> 125000000 | L50: =K50/J50 -> 1 | M50: 0 | N50: 0 | O50: 0 | P50: 0 | Q50: 0 | R50: 0 | S50: 0 | T50: 0 | U50: 125000000 | V50: 0 | W50: 0 | X50: 0 | Y50: 0 | Z50: 0 | AA50: 0 | AB50: 0 | AC50: 0 | AD50: 0 | AE50: 0 | AF50: 125000000 | AG50: 0 | AH50: 0 | AI50: 0 | AJ50: 0 | AK50: 0 | AL50: 0 | AM50: 0 | AN50: 0 | AO50: 0 | AP50: 0 | AQ50: 0 | AS50: 0 | AU50: 0 | AW50: 0 | AY50: 0 | BC50: 0 | BD50: 0
...
